2025-09-17 00:48:33,992 - __main__ - INFO - Logger has been created successfully.
2025-09-17 00:57:54,678 - create_logger - ERROR - An error occurred
Traceback (most recent call last):
  File "c:\Users\User\Desktop\L0W_LEVEL_RAG\utilities\exception.py", line 17, in <module>
    result = 1 / 0  # Example to raise an exception
             ~~^~~
ZeroDivisionError: division by zero
2025-09-17 01:01:33,385 - create_logger - ERROR - An error occurred
Traceback (most recent call last):
  File "c:\Users\User\Desktop\L0W_LEVEL_RAG\utilities\exception.py", line 17, in <module>
    result = 1 / 0  # Example to raise an exception
             ~~^~~
ZeroDivisionError: division by zero
2025-09-17 01:03:56,055 - __main__ - INFO - Logger has been created successfully.
2025-09-17 01:04:38,158 - __main__ - ERROR - An error occurred
Traceback (most recent call last):
  File "c:\Users\User\Desktop\L0W_LEVEL_RAG\utilities\exception.py", line 17, in <module>
    result = 1 / 0  # Example to raise an exception
             ~~^~~
ZeroDivisionError: division by zero
2025-09-17 01:06:30,560 - __main__ - ERROR - An error occurred
Traceback (most recent call last):
  File "c:\Users\User\Desktop\L0W_LEVEL_RAG\utilities\exception.py", line 17, in <module>
    result = 1 / 0  # Example to raise an exception
             ~~^~~
ZeroDivisionError: division by zero
